<?xml version="1.0" ?>
<!-- =================================================================================== -->
<!-- |    This document was autogenerated by xacro from mobilerobot.urdf.xacro         | -->
<!-- |    EDITING THIS FILE BY HAND IS NOT RECOMMENDED                                 | -->
<!-- =================================================================================== -->
<robot name="mobilerobot" xmlns:xacro="http://wiki.ros.org/xacro">
  <link name="base_link">
    <visual>
      <origin rpy="1.57079632679 0 1.57079632679" xyz="0 0 0"/>
      <geometry>
        <mesh filename="package://mobilerobot_description/meshes/base_link.stl" scale="0.001 0.001 0.001"/>
      </geometry>
      <material name="LightGrey">
        <color rgba="0.7 0.7 0.7 1.0"/>
      </material>
    </visual>
    <collision>
      <origin rpy="1.57079632679 0 1.57079632679" xyz="0 0 0"/>
      <geometry>
        <mesh filename="package://mobilerobot_description/meshes/base_link.stl" scale="0.001 0.001 0.001"/>
      </geometry>
      <material name="LightGrey">
        <color rgba="0.7 0.7 0.7 1.0"/>
      </material>
    </collision>
  </link>
  <joint name="forward_left_joint" type="continuous">
    <parent link="base_link"/>
    <child link="forward_left_mecanum_link"/>
    <origin rpy="0 0 0" xyz="0.3 0.3 0.040"/>
    <axis xyz="0 1 0"/>
  </joint>
  <link name="forward_left_mecanum_link">
    <visual>
      <origin rpy="0 0 1.57079632679" xyz="0 -0.13077 0"/>
      <geometry>
        <mesh filename="package://mobilerobot_description/meshes/mecanum_link.stl" scale="0.001 0.001 0.001"/>
      </geometry>
      <material name="LightGrey">
        <color rgba="0.7 0.7 0.7 1.0"/>
      </material>
    </visual>
    <collision>
      <origin rpy="1.57079632679 0 0" xyz="0 0 0"/>
      <geometry>
        <cylinder length="0.041" radius="0.075565"/>
      </geometry>
      <material name="LightGrey">
        <color rgba="0.7 0.7 0.7 1.0"/>
      </material>
    </collision>
  </link>
  <joint name="forward_right_joint" type="continuous">
    <parent link="base_link"/>
    <child link="forward_right_mecanum_link"/>
    <origin rpy="0 0 0" xyz="0.3 -0.3 0.04"/>
    <axis xyz="0 -1 0"/>
  </joint>
  <link name="forward_right_mecanum_link">
    <visual>
      <origin rpy="0 0 -1.57079632679" xyz="0 0.13077 0"/>
      <geometry>
        <mesh filename="package://mobilerobot_description/meshes/mecanum_link.stl" scale="0.001 0.001 0.001"/>
      </geometry>
      <material name="LightGrey">
        <color rgba="0.7 0.7 0.7 1.0"/>
      </material>
    </visual>
    <collision>
      <origin rpy="1.57079632679 0 0" xyz="0 0 0"/>
      <geometry>
        <cylinder length="0.041" radius="0.075565"/>
      </geometry>
      <material name="LightGrey">
        <color rgba="0.7 0.7 0.7 1.0"/>
      </material>
    </collision>
  </link>
  <joint name="backward_left_joint" type="continuous">
    <parent link="base_link"/>
    <child link="backward_left_mecanum_link"/>
    <origin rpy="0 0 0" xyz="-0.3 0.3 0.04"/>
    <axis xyz="0 1 0 "/>
  </joint>
  <link name="backward_left_mecanum_link">
    <visual>
      <origin rpy="0 0 1.57079632679" xyz="0 -0.13077 0"/>
      <geometry>
        <mesh filename="package://mobilerobot_description/meshes/mecanum_link.stl" scale="0.001 0.001 0.001"/>
      </geometry>
      <material name="LightGrey">
        <color rgba="0.7 0.7 0.7 1.0"/>
      </material>
    </visual>
    <collision>
      <origin rpy="1.57079632679 0 0" xyz="0 0 0"/>
      <geometry>
        <cylinder length="0.041" radius="0.075565"/>
      </geometry>
      <material name="LightGrey">
        <color rgba="0.7 0.7 0.7 1.0"/>
      </material>
    </collision>
  </link>
  <joint name="backward_right_joint" type="continuous">
    <parent link="base_link"/>
    <child link="backward_right_mecanum_link"/>
    <origin rpy="0 0 0 " xyz="-0.3 -0.3 0.04"/>
    <axis xyz="0 -1 0"/>
  </joint>
  <link name="backward_right_mecanum_link">
    <visual>
      <origin rpy="0 0 -1.57079632679" xyz="0 0.13077 0"/>
      <geometry>
        <mesh filename="package://mobilerobot_description/meshes/mecanum_link.stl" scale="0.001 0.001 0.001"/>
      </geometry>
      <material name="LightGrey">
        <color rgba="0.7 0.7 0.7 1.0"/>
      </material>
    </visual>
    <collision>
      <origin rpy="1.57079632679 0 0" xyz="0 0 0"/>
      <geometry>
        <cylinder length="0.041" radius="0.075565"/>
      </geometry>
      <material name="LightGrey">
        <color rgba="0.7 0.7 0.7 1.0"/>
      </material>
    </collision>
  </link>
  <transmission name="forward_left_joint_trans">
    <type>transmission_interface/SimpleTransmission</type>
    <joint name="forward_left_joint">
      <hardwareInterface>hardware_interface/VelocityJointInterface</hardwareInterface>
    </joint>
    <actuator name="forward_left_actuator">
      <mechanicalReduction>156</mechanicalReduction>
    </actuator>
  </transmission>
  <transmission name="backward_left_joint_trans">
    <type>transmission_interface/SimpleTransmission</type>
    <joint name="backward_left_joint">
      <hardwareInterface>hardware_interface/VelocityJointInterface</hardwareInterface>
    </joint>
    <actuator name="backward_left_actuator">
      <mechanicalReduction>156</mechanicalReduction>
    </actuator>
  </transmission>
  <transmission name="backward_right_joint_trans">
    <type>transmission_interface/SimpleTransmission</type>
    <joint name="backward_right_joint">
      <hardwareInterface>hardware_interface/VelocityJointInterface</hardwareInterface>
    </joint>
    <actuator name="backward_right_actuator">
      <mechanicalReduction>156</mechanicalReduction>
    </actuator>
  </transmission>
  <transmission name="forward_right_joint_trans">
    <type>transmission_interface/SimpleTransmission</type>
    <joint name="forward_right_joint">
      <hardwareInterface>hardware_interface/VelocityJointInterface</hardwareInterface>
    </joint>
    <actuator name="forward_right_actuator">
      <mechanicalReduction>156</mechanicalReduction>
    </actuator>
  </transmission>
  <link name="link1">
    <visual>
      <origin rpy="0 0 -1.57079632679" xyz="0.09 0 0"/>
      <geometry>
        <mesh filename="package://mobilerobot_description/meshes/manipulator/link1.stl" scale="0.001 0.001 0.001"/>
      </geometry>
      <material name="LightGrey">
        <color rgba="0.7 0.7 0.7 1.0"/>
      </material>
    </visual>
  </link>
  <joint name="joint1" type="revolute">
    <parent link="link1"/>
    <child link="link2"/>
    <origin rpy="0 0 0" xyz="0.126 0 0"/>
    <axis xyz="1 0 0"/>
    <limit effort="1000" lower="-1.57079632679" upper="1.57079632679" velocity="6.5"/>
    <dynamics damping="0.7"/>
  </joint>
  <link name="link2">
    <visual>
      <origin rpy="0 1.57079632679 0" xyz="0.033 0.033 0"/>
      <geometry>
        <mesh filename="package://mobilerobot_description/meshes/manipulator/link2.stl" scale="0.001 0.001 0.001"/>
      </geometry>
      <material name="LightGrey">
        <color rgba="0.7 0.7 0.7 1.0"/>
      </material>
    </visual>
  </link>
  <joint name="joint2" type="revolute">
    <parent link="link2"/>
    <child link="link3"/>
    <origin rpy="0 0 0" xyz="0.033 0.069 0"/>
    <axis xyz="0 1 0"/>
    <limit effort="1000" lower="-1.57079632679" upper="0" velocity="6.5"/>
    <dynamics damping="0.7"/>
  </joint>
  <link name="link3">
    <visual>
      <origin rpy="-1.57079632679 0 0" xyz="0 -0.069 0"/>
      <geometry>
        <mesh filename="package://mobilerobot_description/meshes/manipulator/link3.stl" scale="0.001 0.001 0.001"/>
      </geometry>
      <material name="LightGrey">
        <color rgba="0.7 0.7 0.7 1.0"/>
      </material>
    </visual>
  </link>
  <joint name="joint3" type="revolute">
    <parent link="link3"/>
    <child link="link4"/>
    <origin rpy="0 0 0" xyz="0 -0.069 -0.22541"/>
    <axis xyz="0 0 -1"/>
    <limit effort="1000" lower="-1.57079632679" upper="1.57079632679" velocity="6.5"/>
    <dynamics damping="0.7"/>
  </joint>
  <link name="link4">
    <visual>
      <origin rpy="-1.57079632679 0 0" xyz="0 0 -0.003"/>
      <geometry>
        <mesh filename="package://mobilerobot_description/meshes/manipulator/link4.stl" scale="0.001 0.001 0.001"/>
      </geometry>
      <material name="LightGrey">
        <color rgba="0.7 0.7 0.7 1.0"/>
      </material>
    </visual>
  </link>
  <joint name="joint4" type="revolute">
    <parent link="link4"/>
    <child link="link5"/>
    <origin rpy="0 0 0" xyz="0.03 -0.057 -0.063"/>
    <axis xyz="0 -1 0"/>
    <limit effort="1000" lower="-1.57079632679" upper="1.57079632679" velocity="6.5"/>
    <dynamics damping="0.7"/>
  </joint>
  <link name="link5">
    <visual>
      <origin rpy="-1.57079632679 0 0" xyz="-0.03 0.057 -0.051"/>
      <geometry>
        <mesh filename="package://mobilerobot_description/meshes/manipulator/link5.stl" scale="0.001 0.001 0.001"/>
      </geometry>
      <material name="LightGrey">
        <color rgba="0.7 0.7 0.7 1.0"/>
      </material>
    </visual>
  </link>
  <joint name="joint5" type="revolute">
    <parent link="link5"/>
    <child link="link6"/>
    <origin rpy="0 0 0" xyz="-0.03 0.057 -0.225"/>
    <axis xyz="0 0 -1"/>
    <limit effort="1000" lower="-1.57079632679" upper="1.57079632679" velocity="6.5"/>
    <dynamics damping="0.7"/>
  </joint>
  <link name="link6">
    <visual>
      <origin rpy="-1.57079632679 0 3.14159265359" xyz="0 0 -0.003"/>
      <geometry>
        <mesh filename="package://mobilerobot_description/meshes/manipulator/link6.stl" scale="0.001 0.001 0.001"/>
      </geometry>
      <material name="LightGrey">
        <color rgba="0.7 0.7 0.7 1.0"/>
      </material>
    </visual>
  </link>
  <joint name="joint6" type="revolute">
    <parent link="link6"/>
    <child link="link7"/>
    <origin rpy="0 0 0" xyz="0 0.045 -0.027"/>
    <axis xyz="0 1 0"/>
    <limit effort="1000" lower="-1.57079632679" upper="1.57079632679" velocity="6.5"/>
    <dynamics damping="0.7"/>
  </joint>
  <link name="link7">
    <visual>
      <origin rpy="1.57079632679 0 0" xyz="0 -0.045 -0.049"/>
      <geometry>
        <mesh filename="package://mobilerobot_description/meshes/manipulator/link7.stl" scale="0.001 0.001 0.001"/>
      </geometry>
      <material name="LightGrey">
        <color rgba="0.7 0.7 0.7 1.0"/>
      </material>
    </visual>
  </link>
  <joint name="joint7" type="revolute">
    <parent link="link7"/>
    <child link="end_link"/>
    <origin rpy="0 0 0" xyz="0 -0.045 -0.133"/>
    <axis xyz="0 0 -1"/>
    <limit effort="1000" lower="-1.57079632679" upper="1.57079632679" velocity="6.5"/>
    <dynamics damping="0.7"/>
  </joint>
  <link name="end_link">
    <visual>
      <origin rpy="-1.57079632679 0 0" xyz="0 0 0"/>
      <geometry>
        <mesh filename="package://mobilerobot_description/meshes/manipulator/end_link.stl" scale="0.001 0.001 0.001"/>
      </geometry>
      <material name="LightGrey">
        <color rgba="0.7 0.7 0.7 1.0"/>
      </material>
    </visual>
  </link>
  <transmission name="ball_screw_joint_trans">
    <type>transmission_interface/SimpleTransmission</type>
    <joint name="ball_screw_joint">
      <hardwareInterface>hardware_interface/PositionJointInterface</hardwareInterface>
    </joint>
    <actuator name="oriental_motor_actuator">
      <mechanicalReduction>1</mechanicalReduction>
    </actuator>
  </transmission>
  <link name="world"/>
  <joint name="world_joint" type="fixed">
    <parent link="world"/>
    <child link="base_link"/>
    <origin rpy="0.0 0.0 0.0" xyz="0.0 0.0 0.0"/>
  </joint>
  <joint name="ball_screw_joint" type="prismatic">
    <parent link="base_link"/>
    <child link="ball_screw_link"/>
    <origin rpy="0 0 0" xyz="0.305 0 1.1"/>
    <limit effort="1" lower="-0.77" upper="0" velocity="1"/>
    <axis xyz="0 0 1"/>
  </joint>
  <link name="ball_screw_link">
    <visual>
      <origin rpy="1.57079632679 0 1.57079632679" xyz="0.028 -0.11 0"/>
      <geometry>
        <mesh filename="package://mobilerobot_description/meshes/ball_screw_link.stl" scale="0.001 0.001 0.001"/>
      </geometry>
      <material name="LightGrey">
        <color rgba="0.7 0.7 0.7 1.0"/>
      </material>
    </visual>
  </link>
  <joint name="manipulator_fixed" type="fixed">
    <parent link="ball_screw_link"/>
    <child link="link1"/>
    <origin rpy="0 0 0" xyz="0.048 0 0.075"/>
  </joint>
</robot>
